Traceback (most recent call last):
  File "/Users/mariaoros/Documents/DSI/2026/open_source_survey_results_myst/venv/lib/python3.13/site-packages/jupyter_core/utils/__init__.py", line 154, in wrapped
    asyncio.get_running_loop()
    ~~~~~~~~~~~~~~~~~~~~~~~~^^
RuntimeError: no running event loop

During handling of the above exception, another exception occurred:

Traceback (most recent call last):
  File "/Users/mariaoros/Documents/DSI/2026/open_source_survey_results_myst/venv/lib/python3.13/site-packages/jupyter_cache/executors/utils.py", line 58, in single_nb_execution
    executenb(
    ~~~~~~~~~^
        nb,
        ^^^
    ...<4 lines>...
        **kwargs,
        ^^^^^^^^^
    )
    ^
  File "/Users/mariaoros/Documents/DSI/2026/open_source_survey_results_myst/venv/lib/python3.13/site-packages/nbclient/client.py", line 1319, in execute
    return NotebookClient(nb=nb, resources=resources, km=km, **kwargs).execute()
           ~~~~~~~~~~~~~~~~~~~~~~~~~~~~~~~~~~~~~~~~~~~~~~~~~~~~~~~~~~~~~~~~~~~^^
  File "/Users/mariaoros/Documents/DSI/2026/open_source_survey_results_myst/venv/lib/python3.13/site-packages/jupyter_core/utils/__init__.py", line 158, in wrapped
    return loop.run_until_complete(inner)
           ~~~~~~~~~~~~~~~~~~~~~~~^^^^^^^
  File "/opt/homebrew/Cellar/python@3.13/3.13.7/Frameworks/Python.framework/Versions/3.13/lib/python3.13/asyncio/base_events.py", line 725, in run_until_complete
    return future.result()
           ~~~~~~~~~~~~~^^
  File "/Users/mariaoros/Documents/DSI/2026/open_source_survey_results_myst/venv/lib/python3.13/site-packages/nbclient/client.py", line 709, in async_execute
    await self.async_execute_cell(
        cell, index, execution_count=self.code_cells_executed + 1
    )
  File "/Users/mariaoros/Documents/DSI/2026/open_source_survey_results_myst/venv/lib/python3.13/site-packages/nbclient/client.py", line 1062, in async_execute_cell
    await self._check_raise_for_error(cell, cell_index, exec_reply)
  File "/Users/mariaoros/Documents/DSI/2026/open_source_survey_results_myst/venv/lib/python3.13/site-packages/nbclient/client.py", line 918, in _check_raise_for_error
    raise CellExecutionError.from_cell_and_msg(cell, exec_reply_content)
nbclient.exceptions.CellExecutionError: An error occurred while executing the following cell:
------------------
# Agreement about contributing to OSS being sensible for the university
yes_pct = prop(df["QID19"], lambda s: s == "Yes")
unsure_pct = prop(df["QID19"], lambda s: s == "Not sure")
no_pct = prop(df["QID19"], lambda s: s == "No")

print(f"Should the university contribute to open source:")
print(f"- Yes: {yes_pct}%")
print(f"- Not sure: {unsure_pct}%") 
print(f"- No: {no_pct}%")
------------------


[31m---------------------------------------------------------------------------[39m
[31mNameError[39m                                 Traceback (most recent call last)
[36mCell[39m[36m [39m[32mIn[4][39m[32m, line 2[39m
[32m      1[39m [38;5;66;03m# Agreement about contributing to OSS being sensible for the university[39;00m
[32m----> [39m[32m2[39m yes_pct = [43mprop[49m[43m([49m[43mdf[49m[43m[[49m[33;43m"[39;49m[33;43mQID19[39;49m[33;43m"[39;49m[43m][49m[43m,[49m[43m [49m[38;5;28;43;01mlambda[39;49;00m[43m [49m[43ms[49m[43m:[49m[43m [49m[43ms[49m[43m [49m[43m==[49m[43m [49m[33;43m"[39;49m[33;43mYes[39;49m[33;43m"[39;49m[43m)[49m
[32m      3[39m unsure_pct = prop(df[[33m"[39m[33mQID19[39m[33m"[39m], [38;5;28;01mlambda[39;00m s: s == [33m"[39m[33mNot sure[39m[33m"[39m)
[32m      4[39m no_pct = prop(df[[33m"[39m[33mQID19[39m[33m"[39m], [38;5;28;01mlambda[39;00m s: s == [33m"[39m[33mNo[39m[33m"[39m)

[36mFile [39m[32m~/Documents/DSI/2026/open_source_survey_results_myst/docs/setup.py:108[39m, in [36mprop[39m[34m(series, condition)[39m
[32m    106[39m [38;5;28;01mdef[39;00m[38;5;250m [39m[34mprop[39m(series, condition):
[32m    107[39m     series = series.dropna()
[32m--> [39m[32m108[39m     [38;5;28;01mif[39;00m [38;5;28mlen[39m([43mdf[49m) == [32m0[39m:
[32m    109[39m         [38;5;28;01mreturn[39;00m [32m0.0[39m
[32m    110[39m     [38;5;28;01mreturn[39;00m [38;5;28mround[39m((series[condition(series)].shape[[32m0[39m]) / [38;5;28mlen[39m(df), [32m2[39m) * [32m100[39m

[31mNameError[39m: name 'df' is not defined

