Traceback (most recent call last):
  File "/Users/mariaoros/Documents/DSI/2026/open_source_survey_results_myst/venv/lib/python3.13/site-packages/jupyter_core/utils/__init__.py", line 154, in wrapped
    asyncio.get_running_loop()
    ~~~~~~~~~~~~~~~~~~~~~~~~^^
RuntimeError: no running event loop

During handling of the above exception, another exception occurred:

Traceback (most recent call last):
  File "/Users/mariaoros/Documents/DSI/2026/open_source_survey_results_myst/venv/lib/python3.13/site-packages/jupyter_cache/executors/utils.py", line 58, in single_nb_execution
    executenb(
    ~~~~~~~~~^
        nb,
        ^^^
    ...<4 lines>...
        **kwargs,
        ^^^^^^^^^
    )
    ^
  File "/Users/mariaoros/Documents/DSI/2026/open_source_survey_results_myst/venv/lib/python3.13/site-packages/nbclient/client.py", line 1319, in execute
    return NotebookClient(nb=nb, resources=resources, km=km, **kwargs).execute()
           ~~~~~~~~~~~~~~~~~~~~~~~~~~~~~~~~~~~~~~~~~~~~~~~~~~~~~~~~~~~~~~~~~~~^^
  File "/Users/mariaoros/Documents/DSI/2026/open_source_survey_results_myst/venv/lib/python3.13/site-packages/jupyter_core/utils/__init__.py", line 158, in wrapped
    return loop.run_until_complete(inner)
           ~~~~~~~~~~~~~~~~~~~~~~~^^^^^^^
  File "/opt/homebrew/Cellar/python@3.13/3.13.7/Frameworks/Python.framework/Versions/3.13/lib/python3.13/asyncio/base_events.py", line 725, in run_until_complete
    return future.result()
           ~~~~~~~~~~~~~^^
  File "/Users/mariaoros/Documents/DSI/2026/open_source_survey_results_myst/venv/lib/python3.13/site-packages/nbclient/client.py", line 709, in async_execute
    await self.async_execute_cell(
        cell, index, execution_count=self.code_cells_executed + 1
    )
  File "/Users/mariaoros/Documents/DSI/2026/open_source_survey_results_myst/venv/lib/python3.13/site-packages/nbclient/client.py", line 1062, in async_execute_cell
    await self._check_raise_for_error(cell, cell_index, exec_reply)
  File "/Users/mariaoros/Documents/DSI/2026/open_source_survey_results_myst/venv/lib/python3.13/site-packages/nbclient/client.py", line 918, in _check_raise_for_error
    raise CellExecutionError.from_cell_and_msg(cell, exec_reply_content)
nbclient.exceptions.CellExecutionError: An error occurred while executing the following cell:
------------------
# Imports
import pandas as pd
import plotly.express as px
import plotly.graph_objects as go
from pathlib import Path

# Load data (adjust path if needed)
df = pd.read_csv("data/survey_data.csv")

# Helper: safe proportion
def prop(series, condition):
    series = series.dropna()
    if len(df) == 0:
        return 0.0
    return round((series[condition(series)].shape[0]) / len(df), 2) * 100

# Clean label helpers
def fill_unaffiliated(x):
    return "Unaffiliated" if pd.isna(x) else x

very_valuable_pct = prop(df["QID24"], lambda s: s == "Very valuable")
print(f"Percentage who find vibrant culture 'Very valuable': {very_valuable_pct}%")
------------------


[31m---------------------------------------------------------------------------[39m
[31mModuleNotFoundError[39m                       Traceback (most recent call last)
[36mCell[39m[36m [39m[32mIn[1][39m[32m, line 3[39m
[32m      1[39m [38;5;66;03m# Imports[39;00m
[32m      2[39m [38;5;28;01mimport[39;00m[38;5;250m [39m[34;01mpandas[39;00m[38;5;250m [39m[38;5;28;01mas[39;00m[38;5;250m [39m[34;01mpd[39;00m
[32m----> [39m[32m3[39m [38;5;28;01mimport[39;00m[38;5;250m [39m[34;01mplotly[39;00m[34;01m.[39;00m[34;01mexpress[39;00m[38;5;250m [39m[38;5;28;01mas[39;00m[38;5;250m [39m[34;01mpx[39;00m
[32m      4[39m [38;5;28;01mimport[39;00m[38;5;250m [39m[34;01mplotly[39;00m[34;01m.[39;00m[34;01mgraph_objects[39;00m[38;5;250m [39m[38;5;28;01mas[39;00m[38;5;250m [39m[34;01mgo[39;00m
[32m      5[39m [38;5;28;01mfrom[39;00m[38;5;250m [39m[34;01mpathlib[39;00m[38;5;250m [39m[38;5;28;01mimport[39;00m Path

[31mModuleNotFoundError[39m: No module named 'plotly'

